Workbook

Sheet Model Summary
AO1: created for stair plot
AO2: Used
AO3: year | AP3: MW | AQ3: Adjusted
Y4: Version 15, 2025-07-24 | AO4: 2024 | AP4: =HLOOKUP(AO4,$E$49:$X$50,2) -> 1.8045286 | AQ4: =HLOOKUP($AO4,$E$57:$X$58,2) -> 1.0101286
AO5: 2024.25 | AP5: =AP4 -> 1.8045286 | AQ5: =AQ4 -> 1.0101286
AO6: 2024.25 | AP6: =HLOOKUP(AO6,$E$49:$X$50,2) -> 1.8045286 | AQ6: =HLOOKUP($AO6,$E$57:$X$58,2) -> 1.0101286
AO7: 2024.5 | AP7: =AP6 -> 1.8045286 | AQ7: =AQ6 -> 1.0101286
AO8: 2024.5 | AP8: =HLOOKUP(AO8,$E$49:$X$50,2) -> 1.9559571 | AQ8: =HLOOKUP($AO8,$E$57:$X$58,2) -> 1.1615571
AO9: 2024.75 | AP9: =AP8 -> 1.9559571 | AQ9: =AQ8 -> 1.1615571
AO10: 2024.75 | AP10: =HLOOKUP(AO10,$E$49:$X$50,2) -> 2.2838429 | AQ10: =HLOOKUP($AO10,$E$57:$X$58,2) -> 1.4894429
AO11: 2025 | AP11: =AP10 -> 2.2838429 | AQ11: =AQ10 -> 1.4894429
AO12: 2025 | AP12: =HLOOKUP(AO12,$E$49:$X$50,2) -> 2.2838429 | AQ12: =HLOOKUP($AO12,$E$57:$X$58,2) -> 1.4894429
AO13: 2025.25 | AP13: =AP12 -> 2.2838429 | AQ13: =AQ12 -> 1.4894429
AO14: 2025.25 | AP14: =HLOOKUP(AO14,$E$49:$X$50,2) -> 2.2838429 | AQ14: =HLOOKUP($AO14,$E$57:$X$58,2) -> 1.4894429
AO15: 2025.5 | AP15: =AP14 -> 2.2838429 | AQ15: =AQ14 -> 1.4894429
AO16: 2025.5 | AP16: =HLOOKUP(AO16,$E$49:$X$50,2) -> 2.3484286 | AQ16: =HLOOKUP($AO16,$E$57:$X$58,2) -> 1.4894429
AO17: 2025.75 | AP17: =AP16 -> 2.3484286 | AQ17: =AQ16 -> 1.4894429
AO18: 2025.75 | AP18: =HLOOKUP(AO18,$E$49:$X$50,2) -> 2.5695714 | AQ18: =HLOOKUP($AO18,$E$57:$X$58,2) -> 1.7105857
AO19: 2026 | AP19: =AP18 -> 2.5695714 | AQ19: =AQ18 -> 1.7105857
AO20: 2026 | AP20: =HLOOKUP(AO20,$E$49:$X$50,2) -> 2.5695714 | AQ20: =HLOOKUP($AO20,$E$57:$X$58,2) -> 1.7105857
AO21: 2026.25 | AP21: =AP20 -> 2.5695714 | AQ21: =AQ20 -> 1.7105857
AO22: 2026.25 | AP22: =HLOOKUP(AO22,$E$49:$X$50,2) -> 2.5695714 | AQ22: =HLOOKUP($AO22,$E$57:$X$58,2) -> 1.7105857
AO23: 2026.5 | AP23: =AP22 -> 2.5695714 | AQ23: =AQ22 -> 1.7105857
AO24: 2026.5 | AP24: =HLOOKUP(AO24,$E$49:$X$50,2) -> 2.5695714 | AQ24: =HLOOKUP($AO24,$E$57:$X$58,2) -> 1.7105857
AO25: 2026.75 | AP25: =AP24 -> 2.5695714 | AQ25: =AQ24 -> 1.7105857
AO26: 2026.75 | AP26: =HLOOKUP(AO26,$E$49:$X$50,2) -> 2.5695714 | AQ26: =HLOOKUP($AO26,$E$57:$X$58,2) -> 1.7105857
AO27: 2027 | AP27: =AP26 -> 2.5695714 | AQ27: =AQ26 -> 1.7105857
AO28: 2027 | AP28: =HLOOKUP(AO28,$E$49:$X$50,2) -> 2.5695714 | AQ28: =HLOOKUP($AO28,$E$57:$X$58,2) -> 1.7105857
AO29: 2027.25 | AP29: =AP28 -> 2.5695714 | AQ29: =AQ28 -> 1.7105857
AO30: 2027.25 | AP30: =HLOOKUP(AO30,$E$49:$X$50,2) -> 1.3074429 | AQ30: =HLOOKUP($AO30,$E$57:$X$58,2) -> 0.94845714
AO31: 2027.5 | AP31: =AP30 -> 1.3074429 | AQ31: =AQ30 -> 0.94845714
AO32: 2027.5 | AP32: =HLOOKUP(AO32,$E$49:$X$50,2) -> 1.3074429 | AQ32: =HLOOKUP($AO32,$E$57:$X$58,2) -> 0.94845714
AO33: 2027.75 | AP33: =AP32 -> 1.3074429 | AQ33: =AQ32 -> 0.94845714
AO34: 2027.75 | AP34: =HLOOKUP(AO34,$E$49:$X$50,2) -> 1.3074429 | AQ34: =HLOOKUP($AO34,$E$57:$X$58,2) -> 0.94845714
AO35: 2028 | AP35: =AP34 -> 1.3074429 | AQ35: =AQ34 -> 0.94845714
AO36: 2028 | AP36: =HLOOKUP(AO36,$E$49:$X$50,2) -> 1.3074429 | AQ36: =HLOOKUP($AO36,$E$57:$X$58,2) -> 0.94845714
AO37: 2028.25 | AP37: =AP36 -> 1.3074429 | AQ37: =AQ36 -> 0.94845714
AO38: 2028.25 | AP38: =HLOOKUP(AO38,$E$49:$X$50,2) -> 1.3074429 | AQ38: =HLOOKUP($AO38,$E$57:$X$58,2) -> 0.94845714
AO39: 2028.5 | AP39: =AP38 -> 1.3074429 | AQ39: =AQ38 -> 0.94845714
AO40: 2028.5 | AP40: =HLOOKUP(AO40,$E$49:$X$50,2) -> 0.98344286 | AQ40: =HLOOKUP($AO40,$E$57:$X$58,2) -> 0.62445714
...

Sheet BayView
AU1: created for stair plot
AU2: Used
AU3: year | AV3: MW | AW3: adjusted
AU4: 2024 | AV4: =HLOOKUP(AU4,$K$47:$AD$48,2) -> 0.91212857 | AW4: =HLOOKUP($AU4,$K$45:$AD$46,2) -> 0.91212857
AU5: 2024.25 | AV5: =AV4 -> 0.91212857 | AW5: =AW4 -> 0.91212857
AU6: 2024.25 | AV6: =HLOOKUP(AU6,$K$47:$AD$48,2) -> 0.91212857 | AW6: =HLOOKUP($AU6,$K$45:$AD$46,2) -> 0.91212857
AU7: 2024.5 | AV7: =AV6 -> 0.91212857 | AW7: =AW6 -> 0.91212857
AU8: 2024.5 | AV8: =HLOOKUP(AU8,$K$47:$AD$48,2) -> 0.91212857 | AW8: =HLOOKUP($AU8,$K$45:$AD$46,2) -> 0.91212857
AU9: 2024.75 | AV9: =AV8 -> 0.91212857 | AW9: =AW8 -> 0.91212857
AU10: 2024.75 | AV10: =HLOOKUP(AU10,$K$47:$AD$48,2) -> 1.2400143 | AW10: =HLOOKUP($AU10,$K$45:$AD$46,2) -> 1.2400143
AU11: 2025 | AV11: =AV10 -> 1.2400143 | AW11: =AW10 -> 1.2400143
AU12: 2025 | AV12: =HLOOKUP(AU12,$K$47:$AD$48,2) -> 1.2400143 | AW12: =HLOOKUP($AU12,$K$45:$AD$46,2) -> 1.2400143
AU13: 2025.25 | AV13: =AV12 -> 1.2400143 | AW13: =AW12 -> 1.2400143
AU14: 2025.25 | AV14: =HLOOKUP(AU14,$K$47:$AD$48,2) -> 1.2400143 | AW14: =HLOOKUP($AU14,$K$45:$AD$46,2) -> 1.2400143
AU15: 2025.5 | AV15: =AV14 -> 1.2400143 | AW15: =AW14 -> 1.2400143
AU16: 2025.5 | AV16: =HLOOKUP(AU16,$K$47:$AD$48,2) -> 1.2400143 | AW16: =HLOOKUP($AU16,$K$45:$AD$46,2) -> 1.2400143
AU17: 2025.75 | AV17: =AV16 -> 1.2400143 | AW17: =AW16 -> 1.2400143
AU18: 2025.75 | AV18: =HLOOKUP(AU18,$K$47:$AD$48,2) -> 1.3754429 | AW18: =HLOOKUP($AU18,$K$45:$AD$46,2) -> 1.3754429
AU19: 2026 | AV19: =AV18 -> 1.3754429 | AW19: =AW18 -> 1.3754429
AU20: 2026 | AV20: =HLOOKUP(AU20,$K$47:$AD$48,2) -> 1.3754429 | AW20: =HLOOKUP($AU20,$K$45:$AD$46,2) -> 1.3754429
AU21: 2026.25 | AV21: =AV20 -> 1.3754429 | AW21: =AW20 -> 1.3754429
AU22: 2026.25 | AV22: =HLOOKUP(AU22,$K$47:$AD$48,2) -> 1.3754429 | AW22: =HLOOKUP($AU22,$K$45:$AD$46,2) -> 1.3754429
AU23: 2026.5 | AV23: =AV22 -> 1.3754429 | AW23: =AW22 -> 1.3754429
AU24: 2026.5 | AV24: =HLOOKUP(AU24,$K$47:$AD$48,2) -> 1.3754429 | AW24: =HLOOKUP($AU24,$K$45:$AD$46,2) -> 1.3754429
AU25: 2026.75 | AV25: =AV24 -> 1.3754429 | AW25: =AW24 -> 1.3754429
AU26: 2026.75 | AV26: =HLOOKUP(AU26,$K$47:$AD$48,2) -> 1.3754429 | AW26: =HLOOKUP($AU26,$K$45:$AD$46,2) -> 1.3754429
AU27: 2027 | AV27: =AV26 -> 1.3754429 | AW27: =AW26 -> 1.3754429
AU28: 2027 | AV28: =HLOOKUP(AU28,$K$47:$AD$48,2) -> 1.3754429 | AW28: =HLOOKUP($AU28,$K$45:$AD$46,2) -> 1.3754429
AU29: 2027.25 | AV29: =AV28 -> 1.3754429 | AW29: =AW28 -> 1.3754429
AU30: 2027.25 | AV30: =HLOOKUP(AU30,$K$47:$AD$48,2) -> 0.61331429 | AW30: =HLOOKUP($AU30,$K$45:$AD$46,2) -> 0.61331429
AU31: 2027.5 | AV31: =AV30 -> 0.61331429 | AW31: =AW30 -> 0.61331429
AU32: 2027.5 | AV32: =HLOOKUP(AU32,$K$47:$AD$48,2) -> 0.61331429 | AW32: =HLOOKUP($AU32,$K$45:$AD$46,2) -> 0.61331429
AU33: 2027.75 | AV33: =AV32 -> 0.61331429 | AW33: =AW32 -> 0.61331429
AU34: 2027.75 | AV34: =HLOOKUP(AU34,$K$47:$AD$48,2) -> 0.61331429 | AW34: =HLOOKUP($AU34,$K$45:$AD$46,2) -> 0.61331429
AU35: 2028 | AV35: =AV34 -> 0.61331429 | AW35: =AW34 -> 0.61331429
AU36: 2028 | AV36: =HLOOKUP(AU36,$K$47:$AD$48,2) -> 0.61331429 | AW36: =HLOOKUP($AU36,$K$45:$AD$46,2) -> 0.61331429
AU37: 2028.25 | AV37: =AV36 -> 0.61331429 | AW37: =AW36 -> 0.61331429
AU38: 2028.25 | AV38: =HLOOKUP(AU38,$K$47:$AD$48,2) -> 0.61331429 | AW38: =HLOOKUP($AU38,$K$45:$AD$46,2) -> 0.61331429
AU39: 2028.5 | AV39: =AV38 -> 0.61331429 | AW39: =AW38 -> 0.61331429
AU40: 2028.5 | AV40: =HLOOKUP(AU40,$K$47:$AD$48,2) -> 0.28931429 | AW40: =HLOOKUP($AU40,$K$45:$AD$46,2) -> 0.28931429
...

Sheet Mt.Wash
AU1: created for stair plot
AU2: Used
AU3: year | AV3: MW | AW3: adjusted
AU4: 2024 | AV4: =HLOOKUP(AU4,$K$47:$AD$48,2) -> 0.598 | AW4: =HLOOKUP($AU4,$K$45:$AD$46,2) -> 0.098
AU5: 2024.25 | AV5: =AV4 -> 0.598 | AW5: =AW4 -> 0.098
AU6: 2024.25 | AV6: =HLOOKUP(AU6,$K$47:$AD$48,2) -> 0.598 | AW6: =HLOOKUP($AU6,$K$45:$AD$46,2) -> 0.098
AU7: 2024.5 | AV7: =AV6 -> 0.598 | AW7: =AW6 -> 0.098
AU8: 2024.5 | AV8: =HLOOKUP(AU8,$K$47:$AD$48,2) -> 0.74942857 | AW8: =HLOOKUP($AU8,$K$45:$AD$46,2) -> 0.24942857
AU9: 2024.75 | AV9: =AV8 -> 0.74942857 | AW9: =AW8 -> 0.24942857
AU10: 2024.75 | AV10: =HLOOKUP(AU10,$K$47:$AD$48,2) -> 0.74942857 | AW10: =HLOOKUP($AU10,$K$45:$AD$46,2) -> 0.24942857
N11: adjusted - something in our budget - to estimate for DSAI and other purchases | AU11: 2025 | AV11: =AV10 -> 0.74942857 | AW11: =AW10 -> 0.24942857
AU12: 2025 | AV12: =HLOOKUP(AU12,$K$47:$AD$48,2) -> 0.74942857 | AW12: =HLOOKUP($AU12,$K$45:$AD$46,2) -> 0.24942857
AU13: 2025.25 | AV13: =AV12 -> 0.74942857 | AW13: =AW12 -> 0.24942857
AU14: 2025.25 | AV14: =HLOOKUP(AU14,$K$47:$AD$48,2) -> 0.74942857 | AW14: =HLOOKUP($AU14,$K$45:$AD$46,2) -> 0.24942857
AU15: 2025.5 | AV15: =AV14 -> 0.74942857 | AW15: =AW14 -> 0.24942857
AU16: 2025.5 | AV16: =HLOOKUP(AU16,$K$47:$AD$48,2) -> 0.74942857 | AW16: =HLOOKUP($AU16,$K$45:$AD$46,2) -> 0.24942857
AU17: 2025.75 | AV17: =AV16 -> 0.74942857 | AW17: =AW16 -> 0.24942857
AU18: 2025.75 | AV18: =HLOOKUP(AU18,$K$47:$AD$48,2) -> 0.83514286 | AW18: =HLOOKUP($AU18,$K$45:$AD$46,2) -> 0.33514286
AU19: 2026 | AV19: =AV18 -> 0.83514286 | AW19: =AW18 -> 0.33514286
AU20: 2026 | AV20: =HLOOKUP(AU20,$K$47:$AD$48,2) -> 0.83514286 | AW20: =HLOOKUP($AU20,$K$45:$AD$46,2) -> 0.33514286
AU21: 2026.25 | AV21: =AV20 -> 0.83514286 | AW21: =AW20 -> 0.33514286
AU22: 2026.25 | AV22: =HLOOKUP(AU22,$K$47:$AD$48,2) -> 0.83514286 | AW22: =HLOOKUP($AU22,$K$45:$AD$46,2) -> 0.33514286
AU23: 2026.5 | AV23: =AV22 -> 0.83514286 | AW23: =AW22 -> 0.33514286
AU24: 2026.5 | AV24: =HLOOKUP(AU24,$K$47:$AD$48,2) -> 0.83514286 | AW24: =HLOOKUP($AU24,$K$45:$AD$46,2) -> 0.33514286
AU25: 2026.75 | AV25: =AV24 -> 0.83514286 | AW25: =AW24 -> 0.33514286
AU26: 2026.75 | AV26: =HLOOKUP(AU26,$K$47:$AD$48,2) -> 0.83514286 | AW26: =HLOOKUP($AU26,$K$45:$AD$46,2) -> 0.33514286
AU27: 2027 | AV27: =AV26 -> 0.83514286 | AW27: =AW26 -> 0.33514286
AU28: 2027 | AV28: =HLOOKUP(AU28,$K$47:$AD$48,2) -> 0.83514286 | AW28: =HLOOKUP($AU28,$K$45:$AD$46,2) -> 0.33514286
AU29: 2027.25 | AV29: =AV28 -> 0.83514286 | AW29: =AW28 -> 0.33514286
AU30: 2027.25 | AV30: =HLOOKUP(AU30,$K$47:$AD$48,2) -> 0.33514286 | AW30: =HLOOKUP($AU30,$K$45:$AD$46,2) -> 0.33514286
AU31: 2027.5 | AV31: =AV30 -> 0.33514286 | AW31: =AW30 -> 0.33514286
AU32: 2027.5 | AV32: =HLOOKUP(AU32,$K$47:$AD$48,2) -> 0.33514286 | AW32: =HLOOKUP($AU32,$K$45:$AD$46,2) -> 0.33514286
AU33: 2027.75 | AV33: =AV32 -> 0.33514286 | AW33: =AW32 -> 0.33514286
AU34: 2027.75 | AV34: =HLOOKUP(AU34,$K$47:$AD$48,2) -> 0.33514286 | AW34: =HLOOKUP($AU34,$K$45:$AD$46,2) -> 0.33514286
AU35: 2028 | AV35: =AV34 -> 0.33514286 | AW35: =AW34 -> 0.33514286
AU36: 2028 | AV36: =HLOOKUP(AU36,$K$47:$AD$48,2) -> 0.33514286 | AW36: =HLOOKUP($AU36,$K$45:$AD$46,2) -> 0.33514286
AU37: 2028.25 | AV37: =AV36 -> 0.33514286 | AW37: =AW36 -> 0.33514286
AU38: 2028.25 | AV38: =HLOOKUP(AU38,$K$47:$AD$48,2) -> 0.33514286 | AW38: =HLOOKUP($AU38,$K$45:$AD$46,2) -> 0.33514286
AU39: 2028.5 | AV39: =AV38 -> 0.33514286 | AW39: =AW38 -> 0.33514286
AU40: 2028.5 | AV40: =HLOOKUP(AU40,$K$47:$AD$48,2) -> 0.33514286 | AW40: =HLOOKUP($AU40,$K$45:$AD$46,2) -> 0.33514286
...

Sheet Bloomberg
AU1: created for stair plot
AU2: Used
AU3: year | AV3: MW | AW3: adjusted
AU4: 2024 | AV4: =HLOOKUP(AU4,$K$47:$AD$48,2) -> 0.2944 | AW4: =HLOOKUP($AU4,$K$45:$AD$46,2) -> 0
AU5: 2024.25 | AV5: =AV4 -> 0.2944 | AW5: =AW4 -> 0
AU6: 2024.25 | AV6: =HLOOKUP(AU6,$K$47:$AD$48,2) -> 0.2944 | AW6: =HLOOKUP($AU6,$K$45:$AD$46,2) -> 0
AU7: 2024.5 | AV7: =AV6 -> 0.2944 | AW7: =AW6 -> 0
AU8: 2024.5 | AV8: =HLOOKUP(AU8,$K$47:$AD$48,2) -> 0.2944 | AW8: =HLOOKUP($AU8,$K$45:$AD$46,2) -> 0
AU9: 2024.75 | AV9: =AV8 -> 0.2944 | AW9: =AW8 -> 0
AU10: 2024.75 | AV10: =HLOOKUP(AU10,$K$47:$AD$48,2) -> 0.2944 | AW10: =HLOOKUP($AU10,$K$45:$AD$46,2) -> 0
AU11: 2025 | AV11: =AV10 -> 0.2944 | AW11: =AW10 -> 0
AU12: 2025 | AV12: =HLOOKUP(AU12,$K$47:$AD$48,2) -> 0.2944 | AW12: =HLOOKUP($AU12,$K$45:$AD$46,2) -> 0
AU13: 2025.25 | AV13: =AV12 -> 0.2944 | AW13: =AW12 -> 0
AU14: 2025.25 | AV14: =HLOOKUP(AU14,$K$47:$AD$48,2) -> 0.2944 | AW14: =HLOOKUP($AU14,$K$45:$AD$46,2) -> 0
AU15: 2025.5 | AV15: =AV14 -> 0.2944 | AW15: =AW14 -> 0
AU16: 2025.5 | AV16: =HLOOKUP(AU16,$K$47:$AD$48,2) -> 0.35898571 | AW16: =HLOOKUP($AU16,$K$45:$AD$46,2) -> 0
AU17: 2025.75 | AV17: =AV16 -> 0.35898571 | AW17: =AW16 -> 0
AU18: 2025.75 | AV18: =HLOOKUP(AU18,$K$47:$AD$48,2) -> 0.35898571 | AW18: =HLOOKUP($AU18,$K$45:$AD$46,2) -> 0
AU19: 2026 | AV19: =AV18 -> 0.35898571 | AW19: =AW18 -> 0
AU20: 2026 | AV20: =HLOOKUP(AU20,$K$47:$AD$48,2) -> 0.35898571 | AW20: =HLOOKUP($AU20,$K$45:$AD$46,2) -> 0
AU21: 2026.25 | AV21: =AV20 -> 0.35898571 | AW21: =AW20 -> 0
AU22: 2026.25 | AV22: =HLOOKUP(AU22,$K$47:$AD$48,2) -> 0.35898571 | AW22: =HLOOKUP($AU22,$K$45:$AD$46,2) -> 0
AU23: 2026.5 | AV23: =AV22 -> 0.35898571 | AW23: =AW22 -> 0
AU24: 2026.5 | AV24: =HLOOKUP(AU24,$K$47:$AD$48,2) -> 0.35898571 | AW24: =HLOOKUP($AU24,$K$45:$AD$46,2) -> 0
AU25: 2026.75 | AV25: =AV24 -> 0.35898571 | AW25: =AW24 -> 0
AU26: 2026.75 | AV26: =HLOOKUP(AU26,$K$47:$AD$48,2) -> 0.35898571 | AW26: =HLOOKUP($AU26,$K$45:$AD$46,2) -> 0
AU27: 2027 | AV27: =AV26 -> 0.35898571 | AW27: =AW26 -> 0
AU28: 2027 | AV28: =HLOOKUP(AU28,$K$47:$AD$48,2) -> 0.35898571 | AW28: =HLOOKUP($AU28,$K$45:$AD$46,2) -> 0
AU29: 2027.25 | AV29: =AV28 -> 0.35898571 | AW29: =AW28 -> 0
AU30: 2027.25 | AV30: =HLOOKUP(AU30,$K$47:$AD$48,2) -> 0.35898571 | AW30: =HLOOKUP($AU30,$K$45:$AD$46,2) -> 0
AU31: 2027.5 | AV31: =AV30 -> 0.35898571 | AW31: =AW30 -> 0
AU32: 2027.5 | AV32: =HLOOKUP(AU32,$K$47:$AD$48,2) -> 0.35898571 | AW32: =HLOOKUP($AU32,$K$45:$AD$46,2) -> 0
AU33: 2027.75 | AV33: =AV32 -> 0.35898571 | AW33: =AW32 -> 0
AU34: 2027.75 | AV34: =HLOOKUP(AU34,$K$47:$AD$48,2) -> 0.35898571 | AW34: =HLOOKUP($AU34,$K$45:$AD$46,2) -> 0
AU35: 2028 | AV35: =AV34 -> 0.35898571 | AW35: =AW34 -> 0
AU36: 2028 | AV36: =HLOOKUP(AU36,$K$47:$AD$48,2) -> 0.35898571 | AW36: =HLOOKUP($AU36,$K$45:$AD$46,2) -> 0
AU37: 2028.25 | AV37: =AV36 -> 0.35898571 | AW37: =AW36 -> 0
AU38: 2028.25 | AV38: =HLOOKUP(AU38,$K$47:$AD$48,2) -> 0.35898571 | AW38: =HLOOKUP($AU38,$K$45:$AD$46,2) -> 0
AU39: 2028.5 | AV39: =AV38 -> 0.35898571 | AW39: =AW38 -> 0
AU40: 2028.5 | AV40: =HLOOKUP(AU40,$K$47:$AD$48,2) -> 0.35898571 | AW40: =HLOOKUP($AU40,$K$45:$AD$46,2) -> 0
...

Sheet Baseline Power
J1: this is to account for legacy power (this comes off the calculation)
C3: Calendar Years | D3: Total available power for new computing | I3: IT load used by existing equipment (post Phase I) | N3: Total lT load capacity | T3: Total mechanical load
C4: 0.25 | D4: MARCC | E4: IDIES | F4: Mt. Wash | G4: BayView+ | H4: Total | I4: MARCC | J4: IDIES | K4: Mt. Wash | L4: BayView+ | M4: Total | N4: MARCC | O4: IDIES | P4: Mt. Wash | Q4: BayView+ | R4: BV total | S4: Total | T4: MARCC | U4: IDIES | V4: Mt. Wash | W4: BayView+ | X4: Total
C5: 2024 | D5: =N5-I5 -> 0.45 | E5: =O5-J5 -> 0.125 | F5: =P5-K5 -> 0.37 | G5: =Q5-L5 -> 0 | H5: =SUM(D5:G5) -> 0.945 | I5: 0.75 | J5: 0.325 | K5: 0.68 | L5: 0 | N5: 1.2 | O5: 0.45 | P5: 1.05 | Q5: 0 | R5: =N5+Q5 -> 1.2 | S5: =SUM(N5:Q5) -> 2.7 | T5: 0.3 | U5: 0.1 | V5: 0.4
C6: =C5+$C$4 -> 2024.25 | D6: =N6-I6 -> 0.45 | E6: =O6-J6 -> 0.125 | F6: =P6-K6 -> 0.37 | G6: =Q6-L6 -> 0 | H6: =SUM(D6:G6) -> 0.945 | I6: 0.75 | J6: 0.325 | K6: 0.68 | L6: 0 | N6: 1.2 | O6: 0.45 | P6: 1.05 | Q6: 0 | R6: =N6+Q6 -> 1.2 | S6: =SUM(N6:Q6) -> 2.7 | T6: 0.3 | U6: 0.1 | V6: 0.4
C7: =C6+$C$4 -> 2024.5 | D7: =N7-I7 -> 0.1 | E7: =O7-J7 -> 0.125 | F7: =P7-K7 -> 0.37 | G7: =Q7-L7 -> 0 | H7: =SUM(D7:G7) -> 0.595 | I7: 1.1 | J7: 0.325 | K7: 0.68 | L7: 0 | N7: 1.2 | O7: 0.45 | P7: 1.05 | Q7: 0 | R7: =N7+Q7 -> 1.2 | S7: =SUM(N7:Q7) -> 2.7 | T7: 0.3 | U7: 0.1 | V7: 0.4
C8: =C7+$C$4 -> 2024.75 | D8: =N8-I8 -> 0.1 | E8: =O8-J8 -> 0.125 | F8: =P8-K8 -> 0.47 | G8: =Q8-L8 -> 0 | H8: =SUM(D8:G8) -> 0.695 | I8: 1.1 | J8: 0.325 | K8: 0.58 | L8: 0 | N8: 1.2 | O8: 0.45 | P8: 1.05 | Q8: 0 | R8: =N8+Q8 -> 1.2 | S8: =SUM(N8:Q8) -> 2.7 | T8: 0.3 | U8: 0.1 | V8: 0.4
C9: =C8+$C$4 -> 2025 | D9: =N9-I9 -> 0 | E9: =O9-J9 -> 0.1 | F9: =P9-K9 -> 0.4 | G9: =Q9-L9 -> 0 | H9: =SUM(D9:G9) -> 0.5 | I9: 1.2 | J9: 0.35 | K9: 0.65 | L9: 0 | N9: 1.2 | O9: 0.45 | P9: 1.05 | Q9: 0 | R9: =N9+Q9 -> 1.2 | S9: =SUM(N9:Q9) -> 2.7 | T9: 0.3 | U9: 0.1 | V9: 0.4
C10: =C9+$C$4 -> 2025.25 | D10: =N10-I10 -> 0 | E10: =O10-J10 -> 0.1 | F10: =P10-K10 -> 0.4 | G10: =Q10-L10 -> 0 | H10: =SUM(D10:G10) -> 0.5 | I10: 1.2 | J10: 0.35 | K10: 0.65 | L10: 0 | N10: 1.2 | O10: 0.45 | P10: 1.05 | Q10: 0 | R10: =N10+Q10 -> 1.2 | S10: =SUM(N10:Q10) -> 2.7 | T10: 0.3 | U10: 0.1 | V10: 0.4
C11: =C10+$C$4 -> 2025.5 | D11: =N11-I11 -> 0 | E11: =O11-J11 -> 0.1 | F11: =P11-K11 -> 0.4 | G11: =Q11-L11 -> 0 | H11: =SUM(D11:G11) -> 0.5 | I11: 1.2 | J11: 0.35 | K11: 0.65 | L11: 0 | N11: 1.2 | O11: 0.45 | P11: 1.05 | Q11: 0 | R11: =N11+Q11 -> 1.2 | S11: =SUM(N11:Q11) -> 2.7 | T11: 0.3 | U11: 0.15 | V11: 0.4
C12: =C11+$C$4 -> 2025.75 | D12: =N12-I12 -> 0.8 | E12: =O12-J12 -> 0.1 | F12: =P12-K12 -> 0.4 | G12: =Q12-L12 -> 0 | H12: =SUM(D12:G12) -> 1.3 | I12: 1.2 | J12: 0.35 | K12: 0.65 | L12: 0 | N12: 2 | O12: 0.45 | P12: 1.05 | Q12: 0 | R12: =N12+Q12 -> 2 | S12: =SUM(N12:Q12) -> 3.5 | T12: 0.4 | U12: 0.15 | V12: 0.4
C13: =C12+$C$4 -> 2026 | D13: =N13-I13 -> 0.8 | E13: =O13-J13 -> 0.1 | F13: =P13-K13 -> 0.4 | G13: =Q13-L13 -> 0 | H13: =SUM(D13:G13) -> 1.3 | I13: 1.2 | J13: 0.35 | K13: 0.65 | L13: 0 | N13: 2 | O13: 0.45 | P13: 1.05 | Q13: 0 | R13: =N13+Q13 -> 2 | S13: =SUM(N13:Q13) -> 3.5 | T13: 0.4 | U13: 0.15 | V13: 0.4
C14: =C13+$C$4 -> 2026.25 | D14: =N14-I14 -> 0.8 | E14: =O14-J14 -> 0.1 | F14: =P14-K14 -> 0.4 | G14: =Q14-L14 -> 0 | H14: =SUM(D14:G14) -> 1.3 | I14: 1.2 | J14: 0.35 | K14: 0.65 | L14: 0 | N14: 2 | O14: 0.45 | P14: 1.05 | Q14: 0 | R14: =N14+Q14 -> 2 | S14: =SUM(N14:Q14) -> 3.5 | T14: 0.4 | U14: 0.15 | V14: 0.4
C15: =C14+$C$4 -> 2026.5 | D15: =N15-I15 -> 0.8 | E15: =O15-J15 -> 0.1 | F15: =P15-K15 -> 0.4 | G15: =Q15-L15 -> 0 | H15: =SUM(D15:G15) -> 1.3 | I15: 1.2 | J15: 0.35 | K15: 0.65 | L15: 0 | N15: 2 | O15: 0.45 | P15: 1.05 | Q15: 0 | R15: =N15+Q15 -> 2 | S15: =SUM(N15:Q15) -> 3.5 | T15: 0.4 | U15: 0.15 | V15: 0.4
C16: =C15+$C$4 -> 2026.75 | D16: =N16-I16 -> 0.8 | E16: =O16-J16 -> 0.1 | F16: =P16-K16 -> 0.4 | G16: =Q16-L16 -> 0 | H16: =SUM(D16:G16) -> 1.3 | I16: 1.2 | J16: 0.35 | K16: 0.65 | L16: 0 | N16: 2 | O16: 0.45 | P16: 1.05 | Q16: 0 | R16: =N16+Q16 -> 2 | S16: =SUM(N16:Q16) -> 3.5 | T16: 0.4 | U16: 0.15 | V16: 0.4
C17: =C16+$C$4 -> 2027 | D17: =N17-I17 -> 1.35 | E17: =O17-J17 -> 0.1 | F17: =P17-K17 -> 0.4 | G17: =Q17-L17 -> 0 | H17: =SUM(D17:G17) -> 1.85 | I17: 0.65 | J17: 0.35 | K17: 0.65 | L17: 0 | N17: 2 | O17: 0.45 | P17: 1.05 | Q17: 0 | R17: =N17+Q17 -> 2 | S17: =SUM(N17:Q17) -> 3.5 | T17: 0.4 | U17: 0.15 | V17: 0.8
C18: =C17+$C$4 -> 2027.25 | D18: =N18-I18 -> 1.35 | E18: =O18-J18 -> 0.1 | F18: =P18-K18 -> 0.4 | G18: =Q18-L18 -> 5 | H18: =SUM(D18:G18) -> 6.85 | I18: 0.65 | J18: 0.35 | K18: 0.65 | L18: 0 | N18: 2 | O18: 0.45 | P18: 1.05 | Q18: 5 | R18: =N18+Q18 -> 7 | S18: =SUM(N18:Q18) -> 8.5 | T18: 0.4 | U18: 0.15 | V18: 0.8 | W18: 0.8
C19: =C18+$C$4 -> 2027.5 | D19: =N19-I19 -> 1.35 | E19: =O19-J19 -> 0.1 | F19: =P19-K19 -> 0.4 | G19: =Q19-L19 -> 5 | H19: =SUM(D19:G19) -> 6.85 | I19: 0.65 | J19: 0.35 | K19: 0.65 | L19: 0 | N19: 2 | O19: 0.45 | P19: 1.05 | Q19: 5 | R19: =N19+Q19 -> 7 | S19: =SUM(N19:Q19) -> 8.5 | T19: 0.4 | U19: 0.15 | V19: 0.8 | W19: 0.8
C20: =C19+$C$4 -> 2027.75 | D20: =N20-I20 -> 1.35 | E20: =O20-J20 -> 0.1 | F20: =P20-K20 -> 0.4 | G20: =Q20-L20 -> 5 | H20: =SUM(D20:G20) -> 6.85 | I20: 0.65 | J20: 0.35 | K20: 0.65 | L20: 0 | N20: 2 | O20: 0.45 | P20: 1.05 | Q20: 5 | R20: =N20+Q20 -> 7 | S20: =SUM(N20:Q20) -> 8.5 | T20: 0.4 | U20: 0.15 | V20: 0.8 | W20: 0.8
C21: =C20+$C$4 -> 2028 | D21: =N21-I21 -> 1.55 | E21: =O21-J21 -> 0.1 | F21: =P21-K21 -> 2.2 | G21: =Q21-L21 -> 5 | H21: =SUM(D21:G21) -> 8.85 | I21: 0.45 | J21: 0.35 | K21: 0.65 | L21: 0 | N21: 2 | O21: 0.45 | P21: 2.85 | Q21: 5 | R21: =N21+Q21 -> 7 | S21: =SUM(N21:Q21) -> 10.3 | T21: 0.4 | U21: 0.15 | V21: 0.8 | W21: 0.8
C22: =C21+$C$4 -> 2028.25 | D22: =N22-I22 -> 1.35 | E22: =O22-J22 -> 0 | F22: =P22-K22 -> 2.2 | G22: =Q22-L22 -> 5 | H22: =SUM(D22:G22) -> 8.55 | I22: 0.65 | J22: 0 | K22: 0.65 | L22: 0 | N22: 2 | O22: 0 | P22: 2.85 | Q22: 5 | R22: =N22+Q22 -> 7 | S22: =SUM(N22:Q22) -> 9.85 | T22: 0.4 | U22: 0 | V22: 0.8 | W22: 0.8
C23: =C22+$C$4 -> 2028.5 | D23: =N23-I23 -> 1.35 | E23: =O23-J23 -> 0 | F23: =P23-K23 -> 2.2 | G23: =Q23-L23 -> 5 | H23: =SUM(D23:G23) -> 8.55 | I23: 0.65 | J23: 0 | K23: 0.65 | L23: 0 | N23: 2 | O23: 0 | P23: 2.85 | Q23: 5 | R23: =N23+Q23 -> 7 | S23: =SUM(N23:Q23) -> 9.85 | T23: 0.4 | U23: 0 | V23: 0.8 | W23: 0.8
C24: =C23+$C$4 -> 2028.75 | D24: =N24-I24 -> 1.35 | E24: =O24-J24 -> 0 | F24: =P24-K24 -> 2.2 | G24: =Q24-L24 -> 5 | H24: =SUM(D24:G24) -> 8.55 | I24: 0.65 | J24: 0 | K24: 0.65 | L24: 0 | N24: 2 | O24: 0 | P24: 2.85 | Q24: 5 | R24: =N24+Q24 -> 7 | S24: =SUM(N24:Q24) -> 9.85 | T24: 0.4 | U24: 0 | V24: 0.8 | W24: 0.8
C25: =C24+$C$4 -> 2029 | D25: =N25-I25 -> 1.35 | E25: =O25-J25 -> 0 | F25: =P25-K25 -> 2.2 | G25: =Q25-L25 -> 5 | H25: =SUM(D25:G25) -> 8.55 | I25: 0.65 | J25: 0 | K25: 0.65 | L25: 0 | N25: 2 | O25: 0 | P25: 2.85 | Q25: 5 | R25: =N25+Q25 -> 7 | S25: =SUM(N25:Q25) -> 9.85 | T25: 0.4 | U25: 0 | V25: 0.8 | W25: 0.8
C26: =C25+$C$4 -> 2029.25 | D26: =N26-I26 -> 1.35 | E26: =O26-J26 -> 0 | F26: =P26-K26 -> 2.2 | G26: =Q26-L26 -> 5 | H26: =SUM(D26:G26) -> 8.55 | I26: 0.65 | J26: 0 | K26: 0.65 | L26: 0 | N26: 2 | O26: 0 | P26: 2.85 | Q26: 5 | R26: =N26+Q26 -> 7 | S26: =SUM(N26:Q26) -> 9.85 | T26: 0.4 | U26: 0 | V26: 0.8 | W26: 0.8
C27: =C26+$C$4 -> 2029.5 | D27: =N27-I27 -> 1.35 | E27: =O27-J27 -> 0 | F27: =P27-K27 -> 2.2 | G27: =Q27-L27 -> 5 | H27: =SUM(D27:G27) -> 8.55 | I27: 0.65 | J27: 0 | K27: 0.65 | L27: 0 | N27: 2 | O27: 0 | P27: 2.85 | Q27: 5 | R27: =N27+Q27 -> 7 | S27: =SUM(N27:Q27) -> 9.85 | T27: 0.4 | U27: 0 | V27: 0.8 | W27: 0.8
C28: =C27+$C$4 -> 2029.75 | D28: =N28-I28 -> 1.35 | E28: =O28-J28 -> 0 | F28: =P28-K28 -> 2.2 | G28: =Q28-L28 -> 5 | H28: =SUM(D28:G28) -> 8.55 | I28: 0.65 | J28: 0 | K28: 0.65 | L28: 0 | N28: 2 | O28: 0 | P28: 2.85 | Q28: 5 | R28: =N28+Q28 -> 7 | S28: =SUM(N28:Q28) -> 9.85 | T28: 0.4 | U28: 0 | V28: 0.8 | W28: 0.8
C29: =C28+$C$4 -> 2030 | D29: =N29-I29 -> 1.35 | E29: =O29-J29 -> 0 | F29: =P29-K29 -> 2.2 | G29: =Q29-L29 -> 5 | H29: =SUM(D29:G29) -> 8.55 | I29: 0.65 | J29: 0 | K29: 0.65 | L29: 0 | N29: 2 | O29: 0 | P29: 2.85 | Q29: 5 | R29: =N29+Q29 -> 7 | S29: =SUM(N29:Q29) -> 9.85 | T29: 0.4 | U29: 0 | V29: 0.8 | W29: 0.8
H32: don't change anything in the helper tables - there are for visualization purposes
C33: Helper table for the stairs plot | M33: Helper table for the stairs plot
C34: 2024 | D34: =D5 -> 0.45 | E34: =E5 -> 0.125 | F34: =F5 -> 0.37 | G34: =G5 -> 0 | H34: =H5 -> 0.945 | M34: 2024 | N34: =N5 -> 1.2 | O34: =O5 -> 0.45 | P34: =P5 -> 1.05 | Q34: =Q5 -> 0 | R34: =R5 -> 1.2 | S34: =S5 -> 2.7
C35: 2024.25 | D35: =D34 -> 0.45 | E35: =E34 -> 0.125 | F35: =F34 -> 0.37 | G35: =G34 -> 0 | H35: =H34 -> 0.945 | M35: 2024.25 | N35: =N34 -> 1.2 | O35: =O34 -> 0.45 | P35: =P34 -> 1.05 | Q35: =Q34 -> 0 | R35: =R34 -> 1.2 | S35: =S34 -> 2.7
C36: =C35 -> 2024.25 | D36: =D6 -> 0.45 | E36: =E6 -> 0.125 | F36: =F6 -> 0.37 | G36: =G6 -> 0 | H36: =H6 -> 0.945 | M36: =M35 -> 2024.25 | N36: =N6 -> 1.2 | O36: =O6 -> 0.45 | P36: =P6 -> 1.05 | Q36: =Q6 -> 0 | R36: =R6 -> 1.2 | S36: =S6 -> 2.7
C37: 2024.5 | D37: =D36 -> 0.45 | E37: =E36 -> 0.125 | F37: =F36 -> 0.37 | G37: =G36 -> 0 | H37: =H36 -> 0.945 | M37: 2024.5 | N37: =N36 -> 1.2 | O37: =O36 -> 0.45 | P37: =P36 -> 1.05 | Q37: =Q36 -> 0 | R37: =R36 -> 1.2 | S37: =S36 -> 2.7
C38: =C37 -> 2024.5 | D38: =D7 -> 0.1 | E38: =E7 -> 0.125 | F38: =F7 -> 0.37 | G38: =G7 -> 0 | H38: =H7 -> 0.595 | M38: =M37 -> 2024.5 | N38: =N7 -> 1.2 | O38: =O7 -> 0.45 | P38: =P7 -> 1.05 | Q38: =Q7 -> 0 | R38: =R7 -> 1.2 | S38: =S7 -> 2.7
C39: 2024.75 | D39: =D38 -> 0.1 | E39: =E38 -> 0.125 | F39: =F38 -> 0.37 | G39: =G38 -> 0 | H39: =H38 -> 0.595 | M39: 2024.75 | N39: =N38 -> 1.2 | O39: =O38 -> 0.45 | P39: =P38 -> 1.05 | Q39: =Q38 -> 0 | R39: =R38 -> 1.2 | S39: =S38 -> 2.7
C40: =C39 -> 2024.75 | D40: =D8 -> 0.1 | E40: =E8 -> 0.125 | F40: =F8 -> 0.47 | G40: =G8 -> 0 | H40: =H8 -> 0.695 | M40: =M39 -> 2024.75 | N40: =N8 -> 1.2 | O40: =O8 -> 0.45 | P40: =P8 -> 1.05 | Q40: =Q8 -> 0 | R40: =R8 -> 1.2 | S40: =S8 -> 2.7
C41: 2025 | D41: =D40 -> 0.1 | E41: =E40 -> 0.125 | F41: =F40 -> 0.47 | G41: =G40 -> 0 | H41: =H40 -> 0.695 | M41: 2025 | N41: =N40 -> 1.2 | O41: =O40 -> 0.45 | P41: =P40 -> 1.05 | Q41: =Q40 -> 0 | R41: =R40 -> 1.2 | S41: =S40 -> 2.7
C42: =C41 -> 2025 | D42: =D9 -> 0 | E42: =E9 -> 0.1 | F42: =F9 -> 0.4 | G42: =G9 -> 0 | H42: =H9 -> 0.5 | M42: =M41 -> 2025 | N42: =N9 -> 1.2 | O42: =O9 -> 0.45 | P42: =P9 -> 1.05 | Q42: =Q9 -> 0 | R42: =R9 -> 1.2 | S42: =S9 -> 2.7
C43: 2025.25 | D43: =D42 -> 0 | E43: =E42 -> 0.1 | F43: =F42 -> 0.4 | G43: =G42 -> 0 | H43: =H42 -> 0.5 | M43: 2025.25 | N43: =N42 -> 1.2 | O43: =O42 -> 0.45 | P43: =P42 -> 1.05 | Q43: =Q42 -> 0 | R43: =R42 -> 1.2 | S43: =S42 -> 2.7
...

Sheet Change Log
A4: 45862 | B4: Mt Washington facility - anticipate 24 months to increase by 1.8
B5: Bloomberg facility - anticipate migrating to current Bayview container - and retiring equipment
B6: Added Schmidt infrastructure in current Bayview container
B7: Added Mt Washington - research storage
B8: Note: we need to add some new categories to cover the new equipment - comments in cells

Sheet Power Blocks
C2: The equiment purchased in the later installments can be modified in the yellow cells | P2: Estimated electricity rates for 1kW
C3: The lifecycle of the installed hardware is shown in cells P4..AK20 | P3: location | Q3: $/kW.h | R3: $/kW.yr | S3: inflation
C4: The power of each block is propagated from Col J | P4: Bayview | Q4: 0.1 | R4: =Q4*24*365 -> 876 | S4: 0.1
C5: Add the estimated power for exisiting equipment in the purple cells | P5: MTW | Q5: 0.0755 | R5: =Q5*24*365 -> 661.38
C6: The spreadsheet calculates the total power (needed and available) for every semester | P6: Homewood | Q6: =Q4 -> 0.1 | R6: =Q6*24*365 -> 876
C7: It also shows the total estimated cost (in 2024 $$) | P7: Cooling overhead | S7: 0.2
S10: 2024 | T10: 2024.25 | U10: 2024.5 | V10: 2024.75 | W10: 2025 | X10: 2025.25 | Y10: =X10+0.25 -> 2025.5 | Z10: =Y10+0.25 -> 2025.75 | AA10: =Z10+0.25 -> 2026 | AB10: =AA10+0.25 -> 2026.25 | AC10: =AB10+0.25 -> 2026.5 | AD10: =AC10+0.25 -> 2026.75 | AE10: =AD10+0.25 -> 2027 | AF10: =AE10+0.25 -> 2027.25 | ... AL10: =AK10+0.25 -> 2028.75
P11: =P4 -> Bayview | R11: Hourly | S11: =Q4 -> 0.1 | T11: =S11 -> 0.1 | U11: =T11 -> 0.1 | V11: =U11 -> 0.1 | W11: =V11 -> 0.1 | X11: =W11 -> 0.1 | Y11: =X11*(1+$S$4) -> 0.11 | Z11: =Y11 -> 0.11 | AA11: =Z11 -> 0.11 | AB11: =AA11 -> 0.11 | AC11: =AB11*(1+$S$4) -> 0.121 | AD11: =AC11 -> 0.121 | AE11: =AD11 -> 0.121 | AF11: =AE11 -> 0.121 | AG11: =AF11*(1+$S$4) -> 0.1331 | AH11: =AG11 -> 0.1331 | AI11: =AH11 -> 0.1331 | AJ11: =AI11 -> 0.1331 | AK11: =AJ11*(1+$S$4) -> 0.14641 | AL11: =AK11 -> 0.14641 | AM11: *using current rates and 10% inflation every July
R12: Annual | S12: =S11*24*365 -> 876 | T12: =T11*24*365 -> 876 | U12: =U11*24*365 -> 876 | V12: =V11*24*365 -> 876 | W12: =W11*24*365 -> 876 | X12: =X11*24*365 -> 876 | Y12: =Y11*24*365 -> 963.6 | Z12: =Z11*24*365 -> 963.6 | ... AL12: =AL11*24*365 -> 1282.5516
P13: =P5 -> MTW | R13: Hourly | S13: =Q5 -> 0.0755 | T13: =S13 -> 0.0755 | U13: 0.091 | V13: 0.091 | W13: 0.091 | X13: 0.091 | Y13: 0.091 | Z13: 0.091 | AA13: 0.091 | AB13: 0.091 | AC13: 0.091 | AD13: 0.091 | AE13: 0.091 | AF13: 0.091 | AG13: =AF13*1.1 -> 0.1001 | AH13: =AG13 -> 0.1001 | AI13: =AH13 -> 0.1001 | AJ13: =AI13 -> 0.1001 | AK13: =AJ13*1.1 -> 0.11011 | AL13: =AK13 -> 0.11011 | AM13: * source: Rob Anderson email 11/25/24
R14: Annual | S14: =S13*24*365 -> 661.38 | T14: =T13*24*365 -> 661.38 | U14: =U13*24*365 -> 797.16 | V14: =V13*24*365 -> 797.16 | W14: =W13*24*365 -> 797.16 | X14: =X13*24*365 -> 797.16 | Y14: =Y13*24*365 -> 797.16 | Z14: =Z13*24*365 -> 797.16 | ... AL14: =AL13*24*365 -> 964.5636
P15: =P6 -> Homewood | R15: Hourly | S15: =Q6 -> 0.1 | T15: =S15 -> 0.1 | U15: =T15 -> 0.1 | V15: =U15 -> 0.1 | W15: =V15*(1+$S$4) -> 0.11 | X15: =W15 -> 0.11 | Y15: =X15 -> 0.11 | Z15: =Y15 -> 0.11 | AA15: =Z15*(1+$S$4) -> 0.121 | AB15: =AA15 -> 0.121 | AC15: 0.13165 | AD15: 0.13165 | AE15: =AD15 -> 0.13165 | AF15: =AE15 -> 0.13165 | AG15: 0.13377 | AH15: 0.13377 | AI15: 0.1388 | AJ15: =AI15 -> 0.1388 | AK15: =AJ15 -> 0.1388 | AL15: =AK15 -> 0.1388 | AM15: *source TJ Rosson email 11/21/24
R16: Annual | S16: =S15*24*365 -> 876 | T16: =T15*24*365 -> 876 | U16: =U15*24*365 -> 876 | V16: =V15*24*365 -> 876 | W16: =W15*24*365 -> 963.6 | X16: =X15*24*365 -> 963.6 | Y16: =Y15*24*365 -> 963.6 | Z16: =Z15*24*365 -> 963.6 | ... AL16: =AL15*24*365 -> 1215.888
C18: system | F18: per server | I18: block
C19: name | D19: type | E19: build | F19: price | G19: [kW] | H19: GPU.. | I19: qty | J19: power[MW] | K19: capex | L19: opex [$K] | M19: GPU/CPU | N19: unit
C20: A100-8 | D20: GPU | E20: SMC | F20: 112000 | G20: 10 | H20: 8 | I20: 10 | J20: =I20*G20/1000 -> 0.1 | K20: =I20*F20 -> 1120000 | L20: =J20*$R$4 -> 87.6 | M20: =H20*I20 -> 80 | N20: GPU
C21: H100-4 | D21: GPU | E21: Lenovo | F21: 107000 | G21: 6.25 | H21: 4 | I21: 16 | J21: =I21*G21/1000 -> 0.1 | K21: =I21*F21 -> 1712000 | L21: =J21*$R$4 -> 87.6 | M21: =H21*I21 -> 64 | N21: GPU
C22: H100-8 | D22: GPU | E22: SMC | F22: 250000 | G22: 12.5 | H22: 8 | I22: 8 | J22: =I22*G22/1000 -> 0.1 | K22: =I22*F22 -> 2000000 | L22: =J22*$R$4 -> 87.6 | M22: =H22*I22 -> 64 | N22: GPU
C23: H200-8 | D23: GPU | E23: Dell | F23: 275000 | G23: 10 | H23: 8 | I23: 10 | J23: =I23*G23/1000 -> 0.1 | K23: =I23*F23 -> 2750000 | L23: =J23*$R$4 -> 87.6 | M23: =H23*I23 -> 80 | N23: GPU
C24: L40-8 | D24: GPU | E24: Lenovo | F24: 61300 | G24: 5 | H24: 8 | I24: 20 | J24: =I24*G24/1000 -> 0.1 | K24: =I24*F24 -> 1226000 | L24: =J24*$R$4 -> 87.6 | M24: =H24*I24 -> 160 | N24: GPU
C25: NVL72 | D25: GPU | E25: Nvidia | F25: 7000000 | G25: 135 | H25: 72 | I25: 1 | J25: =I25*G25/1000 -> 0.135 | K25: =I25*F25 -> 7000000 | L25: =J25*$R$4 -> 118.26 | M25: =H25*I25 -> 72 | N25: GPU
C26: HPC1 | D26: CPU | E26: Dell | F26: 10000 | G26: 1 | H26: 128 | I26: 100 | J26: =I26*G26/1000 -> 0.1 | K26: =I26*F26 -> 1000000 | L26: =J26*$R$4 -> 87.6 | M26: =H26*I26 -> 12800 | N26: core
C27: HPC2 | D27: CPU | E27: Dell | F27: 15000 | G27: 1.25 | H27: 256 | I27: 80 | J27: =I27*G27/1000 -> 0.1 | K27: =I27*F27 -> 1200000 | L27: =J27*$R$4 -> 87.6 | M27: =H27*I27 -> 20480 | N27: core
C28: SSD | D28: Sdisk | E28: SMC | F28: 42000 | G28: 0.8 | H28: 0.3 | I28: 125 | J28: =I28*G28/1000 -> 0.1 | K28: =I28*F28 -> 5250000 | L28: =J28*$R$4 -> 87.6 | M28: =H28*I28 -> 37.5 | N28: PB
C29: HDD | D29: Hdisk | E29: SMC | F29: 28571 | G29: =100/140 -> 0.71428571 | H29: 0.53 | I29: 140 | J29: =I29*G29/1000 -> 0.1 | K29: =I29*F29 -> 3999940 | L29: =J29*$R$4 -> 87.6 | M29: =H29*I29 -> 74.2 | N29: PB
C30: V100-4 | D30: GPU | E30: Dell | F30: 20000 | G30: 5 | H30: 4 | I30: 20 | J30: =I30*G30/1000 -> 0.1 | K30: =I30*F30 -> 400000 | L30: =J30*$R$4 -> 87.6 | M30: =H30*I30 -> 80 | N30: GPU
C31: --
